{"uuid": "0cca5351-634a-4703-9d28-5dc1c7aa9023", "children": ["8b4bb6a1-3ba1-4176-8f22-28170d9ba755", "2683af67-7a01-4e36-9e39-1dca476f4dc7"], "befores": [{"name": "setup_teardown", "status": "broken", "statusDetails": {"message": "urllib3.exceptions.MaxRetryError: HTTPConnectionPool(host='localhost', port=4723): Max retries exceeded with url: /session (Caused by NewConnectionError('<urllib3.connection.HTTPConnection object at 0x106ef6c30>: Failed to establish a new connection: [Errno 61] Connection refused'))\n", "trace": "  File \"/Library/Frameworks/Python.framework/Versions/3.12/lib/python3.12/site-packages/pluggy/_callers.py\", line 167, in _multicall\n    teardown.throw(outcome._exception)\n  File \"/Library/Frameworks/Python.framework/Versions/3.12/lib/python3.12/site-packages/_pytest/setuponly.py\", line 36, in pytest_fixture_setup\n    return (yield)\n            ^^^^^\n  File \"/Library/Frameworks/Python.framework/Versions/3.12/lib/python3.12/site-packages/pluggy/_callers.py\", line 103, in _multicall\n    res = hook_impl.function(*args)\n          ^^^^^^^^^^^^^^^^^^^^^^^^^\n  File \"/Library/Frameworks/Python.framework/Versions/3.12/lib/python3.12/site-packages/_pytest/fixtures.py\", line 1140, in pytest_fixture_setup\n    result = call_fixture_func(fixturefunc, request, kwargs)\n             ^^^^^^^^^^^^^^^^^^^^^^^^^^^^^^^^^^^^^^^^^^^^^^^\n  File \"/Library/Frameworks/Python.framework/Versions/3.12/lib/python3.12/site-packages/_pytest/fixtures.py\", line 891, in call_fixture_func\n    fixture_result = next(generator)\n                     ^^^^^^^^^^^^^^^\n  File \"/Volumes/Macintosh HD - Data/PycharmProjects/mobile-android-test/critical_suite.py\", line 98, in setup_teardown\n    driver = webdriver.Remote(url, options=options)\n             ^^^^^^^^^^^^^^^^^^^^^^^^^^^^^^^^^^^^^^\n  File \"/Library/Frameworks/Python.framework/Versions/3.12/lib/python3.12/site-packages/appium/webdriver/webdriver.py\", line 227, in __init__\n    super().__init__(\n  File \"/Library/Frameworks/Python.framework/Versions/3.12/lib/python3.12/site-packages/selenium/webdriver/remote/webdriver.py\", line 241, in __init__\n    self.start_session(capabilities)\n  File \"/Library/Frameworks/Python.framework/Versions/3.12/lib/python3.12/site-packages/appium/webdriver/webdriver.py\", line 319, in start_session\n    response = self.execute(RemoteCommand.NEW_SESSION, w3c_caps)\n               ^^^^^^^^^^^^^^^^^^^^^^^^^^^^^^^^^^^^^^^^^^^^^^^^^\n  File \"/Library/Frameworks/Python.framework/Versions/3.12/lib/python3.12/site-packages/selenium/webdriver/remote/webdriver.py\", line 382, in execute\n    response = self.command_executor.execute(driver_command, params)\n               ^^^^^^^^^^^^^^^^^^^^^^^^^^^^^^^^^^^^^^^^^^^^^^^^^^^^^\n  File \"/Library/Frameworks/Python.framework/Versions/3.12/lib/python3.12/site-packages/selenium/webdriver/remote/remote_connection.py\", line 404, in execute\n    return self._request(command_info[0], url, body=data)\n           ^^^^^^^^^^^^^^^^^^^^^^^^^^^^^^^^^^^^^^^^^^^^^^\n  File \"/Library/Frameworks/Python.framework/Versions/3.12/lib/python3.12/site-packages/selenium/webdriver/remote/remote_connection.py\", line 428, in _request\n    response = self._conn.request(method, url, body=body, headers=headers, timeout=self._client_config.timeout)\n               ^^^^^^^^^^^^^^^^^^^^^^^^^^^^^^^^^^^^^^^^^^^^^^^^^^^^^^^^^^^^^^^^^^^^^^^^^^^^^^^^^^^^^^^^^^^^^^^^\n  File \"/Library/Frameworks/Python.framework/Versions/3.12/lib/python3.12/site-packages/urllib3/_request_methods.py\", line 143, in request\n    return self.request_encode_body(\n           ^^^^^^^^^^^^^^^^^^^^^^^^^\n  File \"/Library/Frameworks/Python.framework/Versions/3.12/lib/python3.12/site-packages/urllib3/_request_methods.py\", line 278, in request_encode_body\n    return self.urlopen(method, url, **extra_kw)\n           ^^^^^^^^^^^^^^^^^^^^^^^^^^^^^^^^^^^^^\n  File \"/Library/Frameworks/Python.framework/Versions/3.12/lib/python3.12/site-packages/urllib3/poolmanager.py\", line 443, in urlopen\n    response = conn.urlopen(method, u.request_uri, **kw)\n               ^^^^^^^^^^^^^^^^^^^^^^^^^^^^^^^^^^^^^^^^^\n  File \"/Library/Frameworks/Python.framework/Versions/3.12/lib/python3.12/site-packages/urllib3/connectionpool.py\", line 871, in urlopen\n    return self.urlopen(\n           ^^^^^^^^^^^^^\n  File \"/Library/Frameworks/Python.framework/Versions/3.12/lib/python3.12/site-packages/urllib3/connectionpool.py\", line 871, in urlopen\n    return self.urlopen(\n           ^^^^^^^^^^^^^\n  File \"/Library/Frameworks/Python.framework/Versions/3.12/lib/python3.12/site-packages/urllib3/connectionpool.py\", line 871, in urlopen\n    return self.urlopen(\n           ^^^^^^^^^^^^^\n  File \"/Library/Frameworks/Python.framework/Versions/3.12/lib/python3.12/site-packages/urllib3/connectionpool.py\", line 841, in urlopen\n    retries = retries.increment(\n              ^^^^^^^^^^^^^^^^^^\n  File \"/Library/Frameworks/Python.framework/Versions/3.12/lib/python3.12/site-packages/urllib3/util/retry.py\", line 519, in increment\n    raise MaxRetryError(_pool, url, reason) from reason  # type: ignore[arg-type]\n    ^^^^^^^^^^^^^^^^^^^^^^^^^^^^^^^^^^^^^^^^^^^^^^^^^^^\n"}, "start": 1736907841859, "stop": 1736907841879}], "start": 1736907841859, "stop": 1736907842334}